<?xml version="1.0" ?>
<robot name="basic_mobile_bot" xmlns:xacro="http://ros.org/wiki/xacro">

    <xacro:include filename="inertial_macros.xacro"/>

    <!-- ****************** ROBOT CONSTANTS *******************************  -->
    <!-- Define the size of the robot's main chassis in meters -->
    <!-- <xacro:property name="base_width" value="0.39"/>
    <xacro:property name="base_length" value="0.70"/>
    <xacro:property name="base_height" value="0.20"/> 
    -->
        
    <!-- Define the shape of the robot's two back wheels in meters -->
    <!-- <xacro:property name="wheel_radius" value="0.14"/>
    <xacro:property name="wheel_width" value="0.06"/> 
    -->

    <!-- x-axis points forward, y-axis points to left, z-axis points upwards -->
    <!-- Define the gap between the wheel and chassis along y-axis in meters -->
    <!-- <xacro:property name="wheel_ygap" value="0.035"/>-->

    <!-- Position the wheels along the z-axis -->
    <!-- <xacro:property name="wheel_zoff" value="0.05"/> 
    -->

    <!-- Position the wheels along the x-axis -->
    <!-- <xacro:property name="wheel_xoff" value="0.221"/>
    -->

    <!-- Position the caster wheel along the x-axis -->
    <!-- <xacro:property name="caster_xoff" value="0.217"/>
    -->
    
    <!-- Color -->
    <material name="white">
        <color rgba="1 1 1 1" />
    </material>

    <material name="orange">
        <color rgba="1 0.3 0.1 1"/>
    </material>

    <material name="blue">
        <color rgba="0.2 0.2 1 1"/>
    </material>

    <material name="black">
        <color rgba="0 0 0 1"/>
    </material>

    <material name="red">
        <color rgba="1 0 0 1"/>
    </material>


    <!-- BASE LINK *********************************************************  -->
    <!-- Define the center of the main robot chassis projected on the ground -->	
    <link name="base_link">
    </link>

    <!-- BASE FOOTPRINT ****************************************************  
    <joint name="base_footprint_joint" type="fixed">
        <parent link="base_link"/>
        <child link="base_footprint"/>
        <origin xyz="0 0 0" rpy="0 0 0"/>
    </joint>

    <link name="base_footprint">
    </link>
    -->

    <!-- CHASSIS ***********************************************************  -->
    <joint name="chassis_joint" type="fixed">
        <parent link="base_link"/>
        <child link="chassis" />
        <origin xyz="-0.043 0 0"/>
    </joint>

    <link name="chassis">
        <visual>
            <origin xyz="0.0915 0 0.0181"/> 
            <geometry>
                <box size="0.183 0.136 0.0548"/>
            </geometry>
            <material name="white"/>
        </visual>

        <collision>
            <origin xyz="0.0915 0 0.0181"/> 
            <geometry>
                <box size="0.183 0.136 0.0548"/>
            </geometry>
        </collision>

        <xacro:inertial_box mass="0.7" x="0.183" y="0.136" z="0.0548">
            <origin xyz="0.0915 0 0.0181" rpy="0 0 0"/>
        </xacro:inertial_box> 
    </link>

    <!-- DRIVE WHEELS *****************************************************  -->
    <!-- LEFT FRONT WHEEL -->
    <joint name="left_front_wheel_joint" type="continuous">
        <parent link="base_link"/>
        <child link="left_front_wheel"/>
        <origin xyz="0.097 0.068 0" rpy="-${pi/2} 0 0"/>
        <axis xyz="0 0 1"/>
    </joint>

    <link name="left_front_wheel">
        <visual>
            <origin xyz="0 0 0"/> 
            <geometry>
                <cylinder radius="0.04" length="0.0425"/>
            </geometry>
            <material name="blue"/>
        </visual>

        <collision>
            <origin xyz="0 0 0"/> 
            <geometry>
                <cylinder radius="0.04" length="0.0425"/>
            </geometry>
        </collision>

        <xacro:inertial_cylinder mass="0.04" radius="0.04" length="0.0425">
            <origin xyz="0 0 0" rpy="0 0 0"/>
        </xacro:inertial_cylinder> 
    </link>

    <!-- RIGHT FRONT WHEEL -->
    <joint name="right_front_wheel_joint" type="continuous">
        <parent link="base_link"/>
        <child link="right_front_wheel"/>
        <origin xyz="0.097 -0.068 0" rpy="${pi/2} 0 0"/>
        <axis xyz="0 0 -1"/>
    </joint>

    <link name="right_front_wheel">
        <visual>
            <origin xyz="0 0 0"/> 
            <geometry>
                <cylinder radius="0.04" length="0.0425"/>
            </geometry>
            <material name="blue"/>
        </visual>

        <collision>
            <origin xyz="0 0 0"/> 
            <geometry>
                <cylinder radius="0.04" length="0.0425"/>
            </geometry>
        </collision>

        <xacro:inertial_cylinder mass="0.04" radius="0.04" length="0.0425">
            <origin xyz="0 0 0" rpy="0 0 0"/>
        </xacro:inertial_cylinder> 
    </link>

    <!-- LEFT REAR WHEEL -->
    <joint name="left_rear_wheel_joint" type="continuous">
        <parent link="base_link"/>
        <child link="left_rear_wheel"/>
        <origin xyz="0 0.068 0" rpy="-${pi/2} 0 0"/>
        <axis xyz="0 0 1"/>
    </joint>

    <link name="left_rear_wheel">
        <visual>
            <origin xyz="0 0 0"/> 
            <geometry>
                <cylinder radius="0.04" length="0.0425"/>
            </geometry>
            <material name="blue"/>
        </visual>

        <collision>
            <origin xyz="0 0 0"/> 
            <geometry>
                <cylinder radius="0.04" length="0.0425"/>
            </geometry>
        </collision>

        <xacro:inertial_cylinder mass="0.04" radius="0.04" length="0.0425">
            <origin xyz="0 0 0" rpy="0 0 0"/>
        </xacro:inertial_cylinder> 
    </link>

    <!-- RIGHT REAR WHEEL -->
    <joint name="right_rear_wheel_joint" type="continuous">
        <parent link="base_link"/>
        <child link="right_rear_wheel"/>
        <origin xyz="0 -0.068 0" rpy="${pi/2} 0 0"/>
        <axis xyz="0 0 -1"/>
    </joint>

    <link name="right_rear_wheel">
        <visual>
            <origin xyz="0 0 0"/> 
            <geometry>
                <cylinder radius="0.04" length="0.0425"/>
            </geometry>
            <material name="blue"/>
        </visual>

        <collision>
            <origin xyz="0 0 0"/> 
            <geometry>
                <cylinder radius="0.04" length="0.0425"/>
            </geometry>
        </collision>

        <xacro:inertial_cylinder mass="0.04" radius="0.04" length="0.0425">
            <origin xyz="0 0 0" rpy="0 0 0"/>
        </xacro:inertial_cylinder> 
    </link>





    <!-- Instantiate two wheels using the macro we just made through the 
        xacro:wheel tags. We also define the parameters to have one wheel
        on both sides at the back of our robot (i.e. x_reflect=-1). -->
    <!-- <xacro:wheel prefix="drivewhl_l" x_reflect="-1" y_reflect="1" />
    <xacro:wheel prefix="drivewhl_r" x_reflect="-1" y_reflect="-1" />
    -->

    <!-- *********************** IMU SETUP *********************************  -->
    <!-- Each sensor must be attached to a link.                              --> 
    
    <!--<joint name="imu_joint" type="fixed">
        <parent link="base_link"/>
        <child link="imu_link"/>
        <origin xyz="-0.10 0 0.05" rpy="0 0 0"/>
    </joint>

    <link name="imu_link"/>
    -->

    <!-- *********************** GPS SETUP **********************************  -->
    <!-- <joint name="gps_joint" type="fixed">
        <parent link="base_link"/>
        <child link="gps_link"/>
        <origin xyz="0.10 0 0.05" rpy="0 0 0"/>
    </joint>

    <link name="gps_link"/>
    -->

</robot>